Traceback (most recent call last):
  File "C:\Users\flobo\anaconda3\envs\make-my-prior\Lib\site-packages\jupyter_cache\executors\utils.py", line 58, in single_nb_execution
    executenb(
  File "C:\Users\flobo\anaconda3\envs\make-my-prior\Lib\site-packages\nbclient\client.py", line 1305, in execute
    return NotebookClient(nb=nb, resources=resources, km=km, **kwargs).execute()
           ^^^^^^^^^^^^^^^^^^^^^^^^^^^^^^^^^^^^^^^^^^^^^^^^^^^^^^^^^^^^^^^^^^^^^
  File "C:\Users\flobo\anaconda3\envs\make-my-prior\Lib\site-packages\jupyter_core\utils\__init__.py", line 166, in wrapped
    return loop.run_until_complete(inner)
           ^^^^^^^^^^^^^^^^^^^^^^^^^^^^^^
  File "C:\Users\flobo\anaconda3\envs\make-my-prior\Lib\asyncio\base_events.py", line 653, in run_until_complete
    return future.result()
           ^^^^^^^^^^^^^^^
  File "C:\Users\flobo\anaconda3\envs\make-my-prior\Lib\site-packages\nbclient\client.py", line 705, in async_execute
    await self.async_execute_cell(
  File "C:\Users\flobo\anaconda3\envs\make-my-prior\Lib\site-packages\nbclient\client.py", line 1058, in async_execute_cell
    await self._check_raise_for_error(cell, cell_index, exec_reply)
  File "C:\Users\flobo\anaconda3\envs\make-my-prior\Lib\site-packages\nbclient\client.py", line 914, in _check_raise_for_error
    raise CellExecutionError.from_cell_and_msg(cell, exec_reply_content)
nbclient.exceptions.CellExecutionError: An error occurred while executing the following cell:
------------------
# internal attributes
print("Total Transactions:", customer.total_transactions())
print("Total Spent:", customer.total_spent())

# descriptive statistics
customer.avg_transaction_amounts_plot(dataset)
customer.customer_segmentation_plot(dataset)
customer.country_distribution_plot(dataset)

spending_category = customer.categorize_spending()
print("Spending Category:", spending_category)
------------------

----- stdout -----
Total Transactions: 297
------------------

[1;31m---------------------------------------------------------------------------[0m
[1;31mTypeError[0m                                 Traceback (most recent call last)
Cell [1;32mIn[5], line 3[0m
[0;32m      1[0m [38;5;66;03m# internal attributes[39;00m
[0;32m      2[0m [38;5;28mprint[39m([38;5;124m"[39m[38;5;124mTotal Transactions:[39m[38;5;124m"[39m, customer[38;5;241m.[39mtotal_transactions())
[1;32m----> 3[0m [38;5;28mprint[39m([38;5;124m"[39m[38;5;124mTotal Spent:[39m[38;5;124m"[39m, [43mcustomer[49m[38;5;241;43m.[39;49m[43mtotal_spent[49m[43m([49m[43m)[49m)
[0;32m      5[0m [38;5;66;03m# descriptive statistics[39;00m
[0;32m      6[0m customer[38;5;241m.[39mavg_transaction_amounts_plot(dataset)

File [1;32m~\anaconda3\envs\make-my-prior\Lib\site-packages\retail\class_customer.py:46[0m, in [0;36mCustomer.total_spent[1;34m(self)[0m
[0;32m     39[0m [38;5;250m[39m[38;5;124;03m"""[39;00m
[0;32m     40[0m [38;5;124;03mCalculate the total amount spent by the customer.[39;00m
[0;32m     41[0m 
[0;32m     42[0m [38;5;124;03mReturns:[39;00m
[0;32m     43[0m [38;5;124;03m- str: The total amount spent by the customer formatted as dollars.[39;00m
[0;32m     44[0m [38;5;124;03m"""[39;00m
[0;32m     45[0m [38;5;66;03m# Convert 'TotalPrice' column to numeric data type[39;00m
[1;32m---> 46[0m [38;5;28;43mself[39;49m[38;5;241;43m.[39;49m[43mtransactions[49m[43m[[49m[38;5;124;43m'[39;49m[38;5;124;43mUnitPrice[39;49m[38;5;124;43m'[39;49m[43m][49m [38;5;241m=[39m pd[38;5;241m.[39mto_numeric([38;5;28mself[39m[38;5;241m.[39mtransactions[[38;5;124m'[39m[38;5;124mUnitPrice[39m[38;5;124m'[39m], errors[38;5;241m=[39m[38;5;124m'[39m[38;5;124mcoerce[39m[38;5;124m'[39m)
[0;32m     47[0m total_spent [38;5;241m=[39m [38;5;28mself[39m[38;5;241m.[39mtransactions[[38;5;124m'[39m[38;5;124mUnitPrice[39m[38;5;124m'[39m][38;5;241m.[39msum()
[0;32m     48[0m [38;5;66;03m# Format the total spent amount as dollars for output[39;00m

File [1;32m~\anaconda3\envs\make-my-prior\Lib\site-packages\polars\dataframe\frame.py:1743[0m, in [0;36mDataFrame.__setitem__[1;34m(self, key, value)[0m
[0;32m   1738[0m [38;5;28;01mif[39;00m [38;5;28misinstance[39m(key, [38;5;28mstr[39m):
[0;32m   1739[0m     msg [38;5;241m=[39m (
[0;32m   1740[0m         [38;5;124m"[39m[38;5;124mDataFrame object does not support `Series` assignment by index[39m[38;5;124m"[39m
[0;32m   1741[0m         [38;5;124m"[39m[38;5;130;01m\n[39;00m[38;5;130;01m\n[39;00m[38;5;124mUse `DataFrame.with_columns`.[39m[38;5;124m"[39m
[0;32m   1742[0m     )
[1;32m-> 1743[0m     [38;5;28;01mraise[39;00m [38;5;167;01mTypeError[39;00m(msg)
[0;32m   1745[0m [38;5;66;03m# df[["C", "D"]][39;00m
[0;32m   1746[0m [38;5;28;01melif[39;00m [38;5;28misinstance[39m(key, [38;5;28mlist[39m):
[0;32m   1747[0m     [38;5;66;03m# TODO: Use python sequence constructors[39;00m

[1;31mTypeError[0m: DataFrame object does not support `Series` assignment by index

Use `DataFrame.with_columns`.

